Workbook

Sheet 📋 Tracker
A1: 🎓 APS APPLICATION TRACKER — Document Verification Portal
A2: Track application status, days elapsed, professor contacts, academic scores & APS probability
A3: SR # | B3: SUBMISSION # | C3: FULL NAME | D3: EMAIL | E3: APPLIED UNIVERSITY | F3: GENDER | G3: DOB | H3: PASSPORT # | I3: CONTACT | J3: DATE OF PAYMENT | K3: APS RECEIVED DATE | L3: DAYS ELAPSED | M3: STATUS | N3: 10TH % | O3: 12TH % | P3: BACHELOR COURSE | Q3: BACHELOR COLLEGE | R3: BACHELOR CITY/STATE | S3: BACHELOR UNIVERSITY | T3: BACHELOR PASS YEAR | U3: BACHELOR % / CGPA | V3: PROFESSOR EMAIL | W3: MASTER COURSE | X3: MASTER COLLEGE | Y3: MASTER UNIVERSITY | Z3: MASTER PASS YEAR | AA3: MASTER % / CGPA | AB3: LANG CERT | AC3: LANG SCORE
A4: 1 | B4: 328041 | C4: Abhishek Chaurasia | D4: abhishekchaurasia590@gmail.com | F4: Male | G4: 23/07/2000 | H4: W4809948 | I4: 7045384665 | J4: 03/12/2025 | K4: 21/01/2026 | L4: =IF(K4<>"",K4-J4,TODAY()-DATE(MID(J4,7,4),MID(J4,4,2),LEFT(J4,2))) | M4: APS Received | N4: 48.4 | O4: 49.23 | P4: B.Com | Q4: Reena Mehta College | R4: Thane | S4: Mumbai University | T4: 2020 | U4: 5.5 CGPA | V4: enquiry@rmc.edu.in | W4: MBA | X4: Rohidas Patil Institute | Y4: Mumbai University | Z4: 2022 | AA4: 7.7 CGPA
A5: 2 | B5: 325697 | C5: Anjum Biradar | D5: anjum.bds@gmail.com | F5: Female | G5: 01/06/1987 | H5: C0301882 | I5: 9986437428 | J5: 19/11/2025 | L5: =IF(K5<>"",K5-J5,TODAY()-DATE(MID(J5,7,4),MID(J5,4,2),LEFT(J5,2))) | M5: Pending | N5: 81.73 | O5: 80.33 | P5: BDS | Q5: R.V Dental College | R5: Bangalore | S5: Rajiv Gandhi Univ of Health Sciences | T5: 2009 | U5: 61.1% / 6.4 CGPA | V5: examination@rguhs.ac.in | W5: PG Diploma | X5: Symbiosis Centre of Health Care | Y5: Symbiosis | Z5: 2014 | AA5: 63.6%
A6: 3 | B6: 351267 | C6: Atul Tayade | D6: tayadeat@gmail.com | F6: Male | G6: 31/12/1988 | H6: AP478200 | I6: 9595872573 | J6: 02/04/2026 | L6: =IF(K6<>"",K6-J6,TODAY()-DATE(MID(J6,7,4),MID(J6,4,2),LEFT(J6,2))) | M6: Pending | N6: 77.6 | O6: 76.17 | P6: BE | Q6: VIIT | R6: Bhusawal | S6: Pune University | T6: 2012 | U6: 49.56% | V6: manohar.kodmelwar@viit.ac.in
A7: 4 | B7: 328137 | C7: Digambar Pawar | D7: dspawar45@hotmail.com | F7: Male | G7: 19/10/1991 | H7: Z8185695 | I7: 9403725008 | J7: 04/12/2025 | K7: 29/01/2026 | L7: =IF(K7<>"",K7-J7,TODAY()-DATE(MID(J7,7,4),MID(J7,4,2),LEFT(J7,2))) | M7: APS Received | N7: 57.23 | O7: 56.67 | P7: B.Tech | Q7: Dept of Technology Shivaji University | R7: Miraj | S7: Shivaji University | T7: 2014 | U7: 64.9% | V7: cja_tech@unishivaji.ac.in
A8: 5 | B8: 350141 | C8: Faiq Faiq | D8: Faiqrizi123@gmail.com | F8: Female | G8: 14/06/1993 | H8: U4858809 | I8: 7051750800 | J8: 26/03/2026 | K8: 28/04/2026 | L8: =IF(K8<>"",K8-J8,TODAY()-DATE(MID(J8,7,4),MID(J8,4,2),LEFT(J8,2))) | M8: APS Received | N8: 86 | O8: 63 | P8: B.Tech | Q8: BUEST | R8: Srinagar | S8: Baddi University | T8: 2019 | U8: 50% / 5.0 CGPA | V8: registrar@baddiuniv.ac.in
A9: 6 | B9: 339028 | C9: Gaurav | D9: gauravjx12@gmail.com | F9: Male | G9: 12/11/1995 | H9: W4984243 | I9: 7056319981 | J9: 02/02/2026 | K9: 16/03/2026 | L9: =IF(K9<>"",K9-J9,TODAY()-DATE(MID(J9,7,4),MID(J9,4,2),LEFT(J9,2))) | M9: APS Received | N9: 77.9 | O9: 67 | P9: B.Tech | Q9: YMCA University | R9: Bahadurgarh | S9: YMCA University of Sci & Tech | T9: 2016 | U9: 50% | V9: result001@jcboseust.ac.in
A10: 7 | B10: 352448 | C10: Hemanth Urs H R | D10: hemanthurs8@gmail.com | F10: Male | G10: 24/03/2002 | H10: AL490525 | I10: 9686593524 | J10: 10/04/2026 | L10: =IF(K10<>"",K10-J10,TODAY()-DATE(MID(J10,7,4),MID(J10,4,2),LEFT(J10,2))) | M10: Pending | N10: 76 | O10: N/A | P10: BE | Q10: Malnad College of Engineering | R10: Hassan | S10: Visvesvaraya Tech University | T10: 2025 | U10: 7.0 CGPA | W10: Still Studying
A11: 8 | B11: 339274 | C11: Lakshana Ragunathan | D11: lakshanar029@gmail.com | F11: Female | G11: 29/06/2003 | H11: AF037641 | I11: 9345881682 | J11: 03/02/2026 | L11: =IF(K11<>"",K11-J11,TODAY()-DATE(MID(J11,7,4),MID(J11,4,2),LEFT(J11,2))) | M11: Pending | N11: 76 | O11: 81 | P11: BE | Q11: Muthayammal Engineering College | R11: Namakkal | S11: Anna University | T11: 2025 | U11: 8.3 CGPA | V11: hod.cse@mec.edu.in
A12: 9 | B12: 334034 | C12: Nagabhushan C R | D12: crnagbhushan@gmail.com | F12: Male | G12: 16/09/1998 | H12: AA442134 | I12: 8197264693 | J12: 08/01/2026 | K12: 2/02/2026 | L12: =IF(K12<>"",K12-J12,TODAY()-DATE(MID(J12,7,4),MID(J12,4,2),LEFT(J12,2))) | M12: APS Received | N12: 86.88 | O12: 70.5 | P12: BE | Q12: RNS Institute of Technology | R12: Bangalore | S12: Visvesvaraya Tech University | T12: 2020 | U12: 61.7% / 6.9 CGPA | V12: hod.civil@rnsit.ac.in
A13: 10 | B13: 344361 | C13: Neha Abhyankar | D13: work.nehaabhyankar@gmail.com | F13: Female | G13: 07/01/1988 | H13: AE453117 | I13: 8390175252 | J13: 25/02/2026 | L13: =IF(K13<>"",K13-J13,TODAY()-DATE(MID(J13,7,4),MID(J13,4,2),LEFT(J13,2))) | M13: Pending | N13: 67.6 | O13: 72 | P13: Bachelor in Foreign Trade | Q13: IIFTR | R13: Pune | S13: Devi Ahilya Vishwavidyalaya | T13: 2008 | U13: 69.38% | V13: registrar.davv@dauniv.ac.in | W13: Masters in Foreign Trade | X13: IIFTR | Y13: Devi Ahilya Vishwavidyalaya | Z13: 2010 | AA13: 70.92%
A14: 11 | B14: 344345 | C14: Nishant Prajapati | D14: nishantprajapati149@gmail.com | F14: Male | G14: 06/04/1999 | H14: AJ805883 | I14: 8160460166 | J14: 25/02/2026 | L14: =IF(K14<>"",K14-J14,TODAY()-DATE(MID(J14,7,4),MID(J14,4,2),LEFT(J14,2))) | M14: Pending | N14: 68.5 | O14: 46.3 | P14: BSc Chemistry | Q14: H.N.S.B Bank Ltd. Science College | R14: Himatnagar | S14: Hemchandracharya North Gujarat Univ | T14: 2019 | U14: 62% / 7.0 CGPA | V14: regi@ngu.ac.in | W14: MSc Organic Chemistry | X14: Nootan Science & Commerce College | Y14: Sakalchand Patel University | Z14: 2021 | AA14: 73.8% / 7.0 CGPA
A15: 12 | B15: 328124 | C15: Prethiviraj B | D15: prethiviraj07@gmail.com | F15: Male | G15: 12/03/2004 | H15: Y7560534 | I15: 9952620642 | J15: 04/12/2025 | K15: 9/12/2025 | L15: =IF(K15<>"",K15-J15,TODAY()-DATE(MID(J15,7,4),MID(J15,4,2),LEFT(J15,2))) | M15: APS Received | N15: 52.8 | O15: 76.2 | P15: B.Tech Mechatronics | Q15: Presidency University | R15: Puducherry | S15: Presidency University | T15: 2025 | U15: 6.3 CGPA | AB15: IELTS | AC15: 6.0
A16: 13 | B16: 334207 | C16: Reacha Kain | D16: richakain28@gmail.com | F16: Female | G16: 28/09/2003 | H16: AB946907 | I16: 7989400738 | J16: 09/01/2026 | K16: 23/01/2026 | L16: =IF(K16<>"",K16-J16,TODAY()-DATE(MID(J16,7,4),MID(J16,4,2),LEFT(J16,2))) | M16: APS Received | N16: 9 | O16: 6.7 | P16: B.Tech CS (Cyber Security) | Q16: Geethanjali College of Engg & Tech | R16: Hyderabad | S16: JNTU Hyderabad | T16: 2025 | U16: 6.7 CGPA | V16: cshead@gcet.edu.in | W16: Still Studying
A17: 14 | B17: 339213 | C17: Rohit Masti | D17: rohitsmasti2003@gmail.com | F17: Male | G17: 13/07/2003 | H17: AL723877 | I17: 9119443028 | J17: 03/02/2026 | K17: 23/02/2026 | L17: =IF(K17<>"",K17-J17,TODAY()-DATE(MID(J17,7,4),MID(J17,4,2),LEFT(J17,2))) | M17: APS Received | N17: 87.6 | O17: 86 | P17: B.Tech CS (AI-ML) | Q17: D.Y. Patil College of Engg, Kolhapur | R17: Kolhapur | S17: Shivaji University Kolhapur | T17: 2025 | U17: 70.53% / 7.5 CGPA | V17: siddheshwarvpatil.dypcet@dypgroup.edu.in
A18: 15 | B18: 346379 | C18: Sachin D. Shingade | D18: shingadesachin6740@gmail.com | F18: Male | G18: 10/06/1988 | H18: W9999537 | I18: 9011944866 | J18: 07/03/2026 | K18: 25/03/2026 | L18: =IF(K18<>"",K18-J18,TODAY()-DATE(MID(J18,7,4),MID(J18,4,2),LEFT(J18,2))) | M18: APS Received | N18: 85.73 | O18: 64 | P18: BE Electronics & Telecom | Q18: Late N.B. Chhabada Inst of Engg | R18: Satara | S18: Shivaji University Kolhapur | T18: 2012 | U18: 68.38% | V18: sfc@unishivaji.ac.in | W18: ME Electronics Digital Systems | X18: VPKBIET Baramati | Y18: Savitribai Phule Pune University | Z18: 2015 | AA18: 7.7 CGPA | AB18: IELTS | AC18: 6.0
A19: 16 | B19: 346561 | C19: Sheikh Nazir Hussain | D19: nayanhussain09@gmail.com | F19: Male | G19: 11/06/1991 | H19: Y2923962 | I19: 9483138766 | J19: 07/03/2026 | K19: 21/04/2026 | L19: =IF(K19<>"",K19-J19,TODAY()-DATE(MID(J19,7,4),MID(J19,4,2),LEFT(J19,2))) | M19: APS Received | N19: 71.66 | O19: 58.67 | P19: BE Mechanical | Q19: R R Institute of Technology | R19: Bangalore | S19: Visvesvaraya Tech University | T19: 2014 | U19: 61.03% | V19: contact@rrinstitutions.in
A20: 17 | B20: 353031 | C20: Sneha Jogi | D20: snehujogi@gmail.com | F20: Female | G20: 15/03/1991 | H20: W1836387 | I20: 8401573867 | J20: 14/04/2026 | L20: =IF(K20<>"",K20-J20,TODAY()-DATE(MID(J20,7,4),MID(J20,4,2),LEFT(J20,2))) | M20: Pending | N20: 74.43 | O20: 63.71 | P20: BCom | Q20: M.P. Shah Municipal Commerce College | R20: Jamnagar | S20: Saurashtra University | T20: 2011 | U20: 59.77% / 5.9 CGPA | V20: info@mpsccjam.org | W20: MCom | X20: M.P. Shah Municipal Commerce College | Y20: Saurashtra University | Z20: 2013 | AA20: 55.08% / 5.5 CGPA
A21: 18 | B21: 331954 | C21: Sujay Laxman H M | D21: sujay.laxman007@gmail.com | F21: Male | G21: 19/03/2003 | H21: AH612160 | I21: 6362448954 | J21: 28/12/2025 | K21: 13/01/2026 | L21: =IF(K21<>"",K21-J21,TODAY()-DATE(MID(J21,7,4),MID(J21,4,2),LEFT(J21,2))) | M21: APS Received | N21: 68.2 | O21: 74.17 | P21: B.Tech Mechanical | Q21: School of Mechanical, Reva University | R21: Bangalore | S21: Reva University | T21: 2025 | U21: 56.92% / 5.9 CGPA | V21: balajis@reva.edu.in
A22: 19 | B22: 335513 | C22: venuvardhan | D22: venuvardhan12@gmail.com | F22: Male | G22: 35630 | H22: C6231371 | I22: 6363791347 | J22: 26/01/2026 | L22: =IF(K22<>"",K22-J22,TODAY()-DATE(MID(J22,7,4),MID(J22,4,2),LEFT(J22,2))) | M22: Pending | N22: 36.8 | O22: 70.09 | P22: Diploma | Q22: Mewar University | R22: Bangalore | S22: Mewar University | T22: 2019 | U22: 73.4/7.3 | V22: amit_kumar@mewaruniversity.co.in
A23: 20 | B23: 346825 | C23: vaishnavi netke | D23: vaishnavinetke2806@gmail.com | F23: Female | G23: 38166 | H23: X2594106 | I23: 9969684420 | J23: 11/03/2026 | K23: 24/03/2026 | L23: =IF(K23<>"",K23-J23,TODAY()-DATE(MID(J23,7,4),MID(J23,4,2),LEFT(J23,2))) | M23: APS Received | N23: 93 | O23: 89.8 | P23: Business Management Studies | Q23: Garware institute of career education and development | R23: Mumbai | S23: Mumbai University | T23: 2025 | U23: 81.81/8.1 | V23: suhas.worlikar@finxpert.org
A24: 21 | B24: 348798 | C24: Ajay Kumar | D24: haritajay20@gmail.com | F24: Male | G24: 33162 | H24: C8658567 | I24: 9896486961 | J24: 10/03/2026 | L24: =IF(K24<>"",K24-J24,TODAY()-DATE(MID(J24,7,4),MID(J24,4,2),LEFT(J24,2))) | M24: Pending | N24: 63 | O24: 66 | P24: BBA | Q24: RKSD College | R24: Kaithal | S24: Kurukshetra Univeristy | T24: 2013 | U24: 52.2 | V24: principal@rksdcollege.ac.in
A25: 22 | B25: 348343 | C25: Sahana Balaram | D25: sahanabalram07@gmail.com | F25: Female | G25: 37820 | H25: AF519649 | I25: 9480150070 | J25: 16/03/2026 | K25: 16/04/2026 | L25: =IF(K25<>"",K25-J25,TODAY()-DATE(MID(J25,7,4),MID(J25,4,2),LEFT(J25,2))) | M25: APS Received | N25: 85 | O25: 91 | P25: B.Com | Q25: KLSE Societys Degree College | R25: Bangalore | S25: Bangalore University | T25: 2024 | U25: 8.5 | V25: madhan17anitha@gmail.com
A26: 23 | B26: 353970 | C26: Kriti Pallavi | D26: kriti.pallavi18@gmail.com | F26: Female | G26: 34667 | H26: Z7183088 | I26: 9717504682 | J26: 21/04/2026 | L26: =IF(K26<>"",K26-J26,TODAY()-DATE(MID(J26,7,4),MID(J26,4,2),LEFT(J26,2))) | M26: Pending | N26: 87.4 | O26: 84 | P26: BDS | Q26: ITS Centre for Dental Studies and Research | R26: Merrut | S26: CCS University | T26: 2018 | U26: 70 | V26: drsaurabhjuneja@gmail.com
A27: 24 | B27: 353102 | C27: Sakina Panvelwala | D27: sakinapanvelwala.35@gmail.com | F27: Female | G27: 37925 | H27: X7321975 | I27: 9372426995 | J27: 16/04/2026 | L27: =IF(K27<>"",K27-J27,TODAY()-DATE(MID(J27,7,4),MID(J27,4,2),LEFT(J27,2))) | M27: Pending | N27: 9.1 | O27: 86.8 | P27: B.Com | Q27: SIES College of Arts, Science and Commerc | R27: Mumbai | S27: Mumbai University | T27: 2025 | U27: 9.1 | V27: bhumikam@sies.edu.in
A28: 25 | B28: 353465 | C28: Neeraj Singh | D28: neerajsingh14414@gmail.com | F28: Male | G28: 37164 | H28: AL285783 | I28: 7078335855 | J28: 17/04/2026 | L28: =IF(K28<>"",K28-J28,TODAY()-DATE(MID(J28,7,4),MID(J28,4,2),LEFT(J28,2))) | M28: Pending | N28: 70.2 | O28: 84.6 | P28: B.com | Q28: Atma Ram Sanatan Dharma College | R28: Delhi | S28: University of Delhi | T28: 2024 | U28: 5.6 | V28: knegi@arsd.du.ac.in
A29: 26 | B29: 354024 | C29: Amatul Haseeb Maseera | D29: haseebamatul143@gmail.com | F29: Female | G29: 34600 | H29: T8372133 | I29: 7396483035 | J29: 21/04/2026 | L29: =IF(K29<>"",K29-J29,TODAY()-DATE(MID(J29,7,4),MID(J29,4,2),LEFT(J29,2))) | M29: Pending | N29: 76.67 | O29: 81.6 | P29: Bachelors of Pharmecy | Q29: MRM College of Pharmecy | R29: Hyderabad | S29: Jawaharlal Nehru Technological University Hyderabad | T29: 2016 | U29: 72.7 | V29: 0 | W29: Post Baccalaureate of Pharmacy | X29: Osmania University Hyderabad | Y29: Osmania University Hyderabad | Z29: 2024 | AA29: 80.58
A30: 27 | B30: 354195 | C30: Adithya Vincent Sindhu | D30: adithyasvincent5@gmail.com | F30: Female | G30: 37506 | H30: AH539447 | I30: 8848511618 | J30: 24/04/2026 | L30: =IF(K30<>"",K30-J30,TODAY()-DATE(MID(J30,7,4),MID(J30,4,2),LEFT(J30,2))) | M30: Pending | N30: 85 | O30: 67.5 | P30: Bachelor’s of vocational studies | Q30: ISDC | S30: Jain deemed to be university | T30: 2024 | U30: 72.76/7.8 | V30: enquiry@jainskills.com
A31: 28 | B31: 354471 | C31: Atharva Kumbhar | D31: atharvapkumbhar@gmail.com | F31: Male | G31: 37880 | H31: AJ512651 | I31: 7738396768 | J31: 24/04/2026 | L31: =IF(K31<>"",K31-J31,TODAY()-DATE(MID(J31,7,4),MID(J31,4,2),LEFT(J31,2))) | M31: Pending | N31: 76.8 | O31: 69.5 | P31: Bachelors in Management Studies | Q31: Ramsheth Thakur College of Science and Commerce | R31: Mumbai | S31: University of Mumbai | T31: 2024 | U31: 6.5
A32: 29 | B32: 354375 | C32: Vanshika Gupta | D32: vanshikag2904@gmail.com | F32: Female | G32: 36279 | H32: AR484959 | I32: 8869886060 | J32: 24/04/2026 | L32: =IF(K32<>"",K32-J32,TODAY()-DATE(MID(J32,7,4),MID(J32,4,2),LEFT(J32,2))) | M32: Pending | N32: 5.6 | O32: 64.8 | P32: B.com | Q32: Hindu College, Moradabad | R32: Moradabad | S32: Mahatma Jyotiba Phule Rohilkhand University, Bareilly | T32: 2020 | U32: 54.7
A33: 30 | B33: 156321 | C33: Apsara Aryal B | D33: apsaraaryal407@gmail.com | F33: Female | G33: 37160 | H33: W4652152 | I33: 9019972317 | J33: 27/12/2023 | K33: 7/02/2024 | L33: =IF(K33<>"",K33-J33,TODAY()-DATE(MID(J33,7,4),MID(J33,4,2),LEFT(J33,2))) | M33: APS Received | N33: 77.44 | O33: 57.66 | P33: B.Com | Q33: Indian academy degree college | R33: Bangalore | S33: Bengaluru north university | T33: 2022 | U33: 7 | V33: principal@iadc.ac.in
A34: 31 | B34: 188013 | C34: Ramij Yeasin | D34: ramijyeasin@gmail.com | F34: Male | G34: 36748 | H34: S7812343 | I34: 7699734865 | J34: 18/04/2023 | L34: =IF(K34<>"",K34-J34,TODAY()-DATE(MID(J34,7,4),MID(J34,4,2),LEFT(J34,2))) | M34: Pending | N34: 49 | O34: 47 | P34: B.com | Q34: BERHAMPORE COLLEGE | R34: Kalyani | S34: UNIVERSITY OF KALYANI | T34: 2022 | U34: 70.67/7.5
A35: 32 | B35: 211708 | C35: Nanda Hanumanth Bhille | D35: nanda.hb98@gmail.com | F35: Female | G35: 401186 | H35: W8894689 | I35: 8904689530 | J35: 19-06-2024 | K35: 17-07-2024 | L35: =IF(K35<>"",K35-J35,TODAY()-DATE(MID(J35,7,4),MID(J35,4,2),LEFT(J35,2))) | M35: APS Received | N35: 76.32 | O35: 64 | P35: B.Tech | Q35: Visvesvaraya Technological University, Belagav | R35: Bangalore | S35: Dayananda Sagar Academy of Technology and Management | T35: 2020 | U35: 7.1 | V35: ashok-me@dsatm.edu.in
A36: 33 | B36: 287590 | C36: Suraj Damodaran | D36: surajdamodaran12@gmail.com | F36: Male | G36: 44694 | H36: V3821113 | I36: 8882630752 | J36: 31/03/2025 | K36: 14/05/2025 | L36: =IF(K36<>"",K36-J36,TODAY()-DATE(MID(J36,7,4),MID(J36,4,2),LEFT(J36,2))) | M36: APS Received | N36: 79.6 | O36: 65.4 | P36: B.SC(HONS) Agriculture | Q36: Amity Institute of Organic Agriculture | R36: Noida | S36: Amity University | T36: 2024 | U36: 7.2 | V36: dsgaikwad@amity.edu
A37: 34 | B37: 270074 | C37: Laxmi Varshitha Reddy Thummeti | D37: thummetivarshithareddy0208@gmail.com | F37: Female | G37: 02/05/2003 | H37: Y5312184 | I37: 6305549634 | J37: 20/01/2025 | K37: 28/02/2025 | L37: =IF(K37<>"",K37-J37,TODAY()-DATE(MID(J37,7,4),MID(J37,4,2),LEFT(J37,2))) | M37: APS Received | N37: 8.5 | O37: 88.1 | P37: B.Tech (ECE) | Q37: CMR College of Engineering & Technology | R37: Hyderabad | S37: Jawaharlal Nehru Technological University Hyderabad | T37: 2024 | U37: 8.6 CGPA | V37: 20h51a0479@cmrcet.ac.in | AB37: TOEFL
A38: 35 | B38: 294557 | C38: Elangovan Sakthivel | D38: selangovan263@gmail.com | F38: Male | G38: 17/10/1996 | H38: C8311240 | I38: 9500356731 | J38: 13/05/2025 | K38: 14/07/2025 | L38: =IF(K38<>"",K38-J38,TODAY()-DATE(MID(J38,7,4),MID(J38,4,2),LEFT(J38,2))) | M38: APS Received | N38: 81.4 | O38: 60.6 | P38: B.Sc (Information Technology) | Q38: Sri Krishna Arts and Science College | R38: Coimbatore | S38: Bharathiyar University | T38: 2017 | U38: 53.7% / 5.2 CGPA | V38: principal@skasc.ac.in | AB38: IELTS
A39: 36 | B39: 296978 | C39: Melwin Paul | D39: melwinpaul2002@gmail.com | F39: Male | G39: 10/05/2002 | H39: V6369952 | I39: 06201295031 | J39: 22/05/2025 | K39: 16/06/2025 | L39: =IF(K39<>"",K39-J39,TODAY()-DATE(MID(J39,7,4),MID(J39,4,2),LEFT(J39,2))) | M39: APS Received | N39: 77.8 | O39: 83.5 | P39: B.Com (Honors) | Q39: X.I.T.E. Gamharia | R39: Jamshedpur | S39: Kolhan University | T39: 2024 | U39: 71.21% / 7.7 CGPA | V39: info@xite.ac.in | AB39: IELTS
A40: 37 | B40: 293262 | C40: Vamsy Appalla | D40: vamsy.appalla@gmail.com | F40: Male | G40: 27/12/2001 | H40: C8410793 | I40: 9100184777 | J40: 29/04/2025 | K40: 24/06/2025 | L40: =IF(K40<>"",K40-J40,TODAY()-DATE(MID(J40,7,4),MID(J40,4,2),LEFT(J40,2))) | M40: APS Received | N40: 73 | O40: 65.4 | P40: BBA (Marketing) | Q40: Amity University | R40: Hyderabad | S40: Amity University | T40: 2024 | U40: 93.5% / 9.3 CGPA | V40: admissions@amity.edu | AB40: IELTS
...

Sheet 📊 Summary
A1: APS TRACKER — SUMMARY DASHBOARD
A3: Total Applications | C3: Pending | E3: APS Received | G3: High Chances | I3: Avg Days (filled)
A5: =COUNTA('📋 Tracker'!C4:C299) | C5: =COUNTIF('📋 Tracker'!M4:M299,"Pending") | E5: =COUNTIF('📋 Tracker'!M4:M299,"APS Received") | G5: =COUNTIF('📋 Tracker'!#REF!,"🟢 HIGH") | I5: =AVERAGEIFS('📋 Tracker'!L4:L81, '📋 Tracker'!M4:M81, "APS Received")
A9: Category | B9: =COUNTA('📋 Tracker'!C4:C21) | C9: % of Total
A10: 🟢 High Chances | B10: =COUNTIF('📋 Tracker'!#REF!,"🟢 HIGH") | C10: =B10/B9*100
A11: 🟡 Moderate Chances | B11: =COUNTIF('📋 Tracker'!#REF!,"🟡 MODERATE") | C11: =B11/B9*100
A12: 🔴 Low Chances | B12: =COUNTIF('📋 Tracker'!#REF!,"🔴 LOW") | C12: =B12/B9*100
A13: ⚪ Needs Review | B13: =COUNTIF('📋 Tracker'!#REF!,"⚪ NEEDS REVIEW") | C13: =B13/B9*100
A15: Earliest Application | B15: Earliest
A16: Latest Application | B16: Latest
A19: 📌 HOW TO USE: 1) Update APS Received Date (col J) in Tracker when APS arrives 2) Days Elapsed auto-calculates 3) Change Status dropdown (col L) to reflect current state 4) Fill Applied University (col AC) & APS Score (col AD) once known

Sheet 📬 Prof Contacts
A1: PROFESSOR & INSTITUTION CONTACT DIRECTORY
A2: 0 | B2: 0 | C2: 0 | D2: 0 | E2: 0
A3: 0 | B3: FULL NAME | C3: BACHELOR COLLEGE | D3: BACHELOR COURSE | E3: PROFESSOR EMAIL | F3: CONTACTED
A4: 1 | B4: Abhishek Chaurasia | C4: Reena Mehta College | D4: B.Com | E4: enquiry@rmc.edu.in | F4: No
A5: 2 | B5: Anjum Biradar | C5: R.V Dental College | D5: BDS | E5: examination@rguhs.ac.in | F5: No
A6: 3 | B6: Atul Tayade | C6: VIIT | D6: ś | E6: manohar.kodmelwar@viit.ac.in | F6: No
A7: 4 | B7: Digambar Pawar | C7: Dept of Technology Shivaji University | D7: B.Tech | E7: cja_tech@unishivaji.ac.in | F7: No
A8: 5 | B8: Faiq Faiq | C8: BUEST | D8: B.Tech | E8: registrar@baddiuniv.ac.in | F8: No
A9: 6 | B9: Gaurav | C9: YMCA University | D9: B.Tech | E9: result001@jcboseust.ac.in | F9: No
A10: 7 | B10: Hemanth Urs H R | C10: Malnad College of Engineering | D10: BE | E10: 0 | F10: No
A11: 8 | B11: Huynh Thao Muoi | C11: University of Information Technology – VNUHCM | D11: BSc | E11: 0 | F11: No
A12: 9 | B12: Lakshana Ragunathan | C12: Muthayammal Engineering College | D12: BE | E12: hod.cse@mec.edu.in | F12: No
A13: 10 | B13: Nagabhushan C R | C13: RNS Institute of Technology | D13: BE | E13: hod.civil@rnsit.ac.in | F13: No
A14: 11 | B14: Neha Abhyankar | C14: IIFTR | D14: Bachelor in Foreign Trade | E14: registrar.davv@dauniv.ac.in | F14: No
A15: 12 | B15: Nishant Prajapati | C15: H.N.S.B Bank Ltd. Science College | D15: BSc Chemistry | E15: regi@ngu.ac.in | F15: No
A16: 13 | B16: Prethiviraj B | C16: Presidency University | D16: B.Tech Mechatronics | E16: 0 | F16: No
A17: 14 | B17: Reacha Kain | C17: Geethanjali College of Engg & Tech | D17: B.Tech CS (Cyber Security) | E17: cshead@gcet.edu.in | F17: No
A18: 15 | B18: Rohit Masti | C18: D.Y. Patil College of Engg, Kolhapur | D18: B.Tech CS (AI-ML) | E18: siddheshwarvpatil.dypcet@dypgroup.edu.in | F18: No
A19: 16 | B19: Sachin D. Shingade | C19: Late N.B. Chhabada Inst of Engg | D19: BE Electronics & Telecom | E19: sfc@unishivaji.ac.in | F19: No
A20: 17 | B20: Sheikh Nazir Hussain | C20: R R Institute of Technology | D20: BE Mechanical | E20: contact@rrinstitutions.in | F20: No
A21: 18 | B21: Sneha Jogi | C21: M.P. Shah Municipal Commerce College | D21: BCom | E21: info@mpsccjam.org | F21: No
A22: 19 | B22: Sujay Laxman H M | C22: School of Mechanical, Reva University | D22: B.Tech Mechanical | E22: balajis@reva.edu.in | F22: No
A23: 20 | B23: venuvardhan | C23: Mewar University | D23: Diploma | E23: amit_kumar@mewaruniversity.co.in | F23: No
A24: 21 | B24: vaishnavi netke | C24: Garware institute of career education and development | D24: Business Management Studies | E24: suhas.worlikar@finxpert.org | F24: No
A25: 22 | B25: Ajay Kumar | C25: RKSD College | D25: BBA | E25: principal@rksdcollege.ac.in | F25: No
A26: 23 | B26: Sahana Balaram | C26: KLSE Societys Degree College | D26: B.Com | E26: madhan17anitha@gmail.com | F26: No
A27: 24 | B27: Kriti Pallavi | C27: ITS Centre for Dental Studies and Research | D27: BDS | E27: drsaurabhjuneja@gmail.com | F27: No
A28: 25 | B28: Sakina Panvelwala | C28: SIES College of Arts, Science and Commerc | D28: B.Com | E28: bhumikam@sies.edu.in | F28: No
A29: 26 | B29: Neeraj Singh | C29: Atma Ram Sanatan Dharma College | D29: B.com | E29: knegi@arsd.du.ac.in | F29: No
A30: 27 | B30: Amatul Haseeb Maseera | C30: MRM College of Pharmecy | D30: Bachelors of Pharmecy | E30: 0 | F30: No
A31: 28 | B31: Adithya Vincent Sindhu | C31: ISDC | D31: Bachelor’s of vocational studies | E31: enquiry@jainskills.com | F31: No
A32: 29 | B32: Atharva Kumbhar | C32: Ramsheth Thakur College of Science and Commerce | D32: Bachelors in Management Studies | E32: 0 | F32: No
A33: 30 | B33: Vanshika Gupta | C33: Hindu College, Moradabad | D33: Mahatma Jyotiba Phule Rohilkhand University, Bareilly | E33: 0 | F33: No
A34: 31 | B34: ='📋 Tracker'!C37 | C34: CMR College of Engineering & Technology | D34: ='📋 Tracker'!P37 | E34: ='📋 Tracker'!V37 | F34: No
A35: 32 | B35: ='📋 Tracker'!C38 | C35: ='📋 Tracker'!Q38 | D35: ='📋 Tracker'!P38 | E35: ='📋 Tracker'!V38 | F35: No
A36: 33 | B36: ='📋 Tracker'!C39 | C36: ='📋 Tracker'!Q39 | D36: ='📋 Tracker'!P39 | E36: ='📋 Tracker'!V39 | F36: No
A37: 34 | B37: ='📋 Tracker'!C40 | C37: ='📋 Tracker'!Q40 | D37: ='📋 Tracker'!P40 | E37: ='📋 Tracker'!V40 | F37: No
A38: 35 | B38: ='📋 Tracker'!C41 | C38: ='📋 Tracker'!Q41 | D38: ='📋 Tracker'!P41 | E38: ='📋 Tracker'!V41 | F38: No
A39: 36 | B39: ='📋 Tracker'!C42 | C39: ='📋 Tracker'!Q42 | D39: ='📋 Tracker'!P42 | E39: ='📋 Tracker'!V42 | F39: No
A40: 37 | B40: ='📋 Tracker'!C43 | C40: ='📋 Tracker'!Q43 | D40: ='📋 Tracker'!P43 | E40: ='📋 Tracker'!V43 | F40: No
...
